Workbook

Sheet Techniques
A1: Technique | B1: (1) data/memory structure | C1: (2) algorithm implementation | D1: (3) arithmetic/logic operations | E1: (4) loops
A2: T4 | E2: x
A3: T5 | C3: x
A4: T7 | B4: x | C4: x
A5: T8 | B5: x | C5: x
A6: T9 | C6: x
A7: T10 | C7: x | E7: x
A8: T11 | B8: x | E8: x
A9: T12 | C9: x
A10: T13 | B10: x | E10: x
A11: T16 | D11: x
A12: T17 | D12: x
A13: T19 | C13: x | E13: x
A14: T20 | C14: x | E14: x
A15: T25 | C15: x | E15: x
A16: T26 | C16: x | E16: x
A17: T28 | E17: x
A18: T29 | D18: x
A19: T31 | C19: x
A20: T32 | C20: x
A21: T33 | C21: x
A22: T36 | E22: x
A23: T40 | E23: x
A24: T44 | D24: x
A25: T49 | C25: x
A26: T50 | C26: x
A27: T51 | C27: x

Sheet Implementation
A1: ID | B1: Name | C1: Programming language
C2: C | D2: Python | E2: Java
A3: T01 | B3: Bit Fields | C3: x | D3: Does not have Bit Fields. | E3: Does not have Bit Fields.
A4: T02 | B4: Bit Sets | C4: x | D4: Does not have built-in support for Bit Sets. | E4: Does not have built-in support for Bit Sets.
A5: T03 | B5: Boolean Return | C5: x | D5: Does not support returning multiple boolean values as a single unsigned int. | E5: Does not support returning multiple boolean values as a single unsigned int.
A6: T04 | B6: Cascaded Function Calls | C6: x | D6: x | E6: x
A7: T05 | B7: Row Major Accesing | C7: x | D7: x | E7: x
A8: T06 | B8: Constructor Initialization Lists | C8: x | D8: Does not support constructor initialization lists. | E8: Does not support constructor initialization lists.
A9: T07 | B9: Common Subexpression Elimination | C9: x | D9: x | E9: x
A10: T08 | B10: Mapping Estructures | C10: x | D10: x | E10: x
A11: T09 | B11: Dead Code Elimination | C11: x | D11: x | E11: x
A12: T10 | B12: Exception Handling | C12: x | D12: x | E12: x
A13: T11 | B13: Global Variables Within Loops | C13: x | D13: x | E13: x
A14: T12 | B14: Function Inlining | C14: x | D14: x | E14: x
... A50: T51 | B50: Coarsening Recursion | C50: x | D50: x | E50: x

Sheet C Impact of Technique
A1: Tecnica | B1: Optimization | C1: Test | D1: Time (s) | E1: Power | H1: Consumption (with baseline) | K1: Consumption (without baseline) | N1: Impact of Technique ((Test2-Test1)/Test1%)
E2: HDD (w) | F2: CPU (w) | G2: DUT (w) | H2: HDD (J) | I2: CPU (J) | J2: DUT (J) | K2: HDD (J) | L2: CPU (J) | M2: DUT (J) | N2: Time (s) | O2: HDD (J) | P2: CPU (J) | Q2: DUT (J)
A3: T04 | B3: O0 | C3: Test1 | D3: 4.713 | E3: 3.48 | F3: 22.78 | G3: 132.94 | H3: 16.40124 | I3: 107.36214 | J3: 626.54622 | K3: 14.42178 | L3: 104.6286 | M3: 242.2482 | N3: =(D4-D3)/D3 -> -0.22236367 | O3: =(K4-K3)/K3 -> -0.21728108 | P3: =(L4-L3)/L3 -> -0.32709938 | Q3: =(M4-M3)/M3 -> -0.32024903
C4: Test2 | D4: 3.665 | E4: 3.5 | F4: 19.79 | G4: 126.47 | H4: 12.8275 | I4: 72.53035 | J4: 463.51255 | K4: 11.2882 | L4: 70.40465 | M4: 164.66845
B5: O3 | C5: Test1 | D5: 3.071 | E5: 3.51 | F5: 19.7 | G5: 126.64 | H5: 10.77921 | I5: 60.4987 | J5: 388.91144 | K5: 9.48939 | L5: 58.71752 | M5: 138.5021 | N5: =(D6-D5)/D5 -> -0.65874308 | O5: =(K6-K5)/K5 -> -0.65101234 | P5: =(L6-L5)/L5 -> -0.80045751 | Q5: =(M6-M5)/M5 -> -0.7705785
C6: Test2 | D6: 1.048 | E6: 3.58 | F6: 11.76 | G6: 111.86 | H6: 3.75184 | I6: 12.32448 | J6: 117.22928 | K6: 3.31168 | L6: 11.71664 | M6: 31.77536
A7: T05 | B7: O0 | C7: Test1 | D7: 409.731 | E7: 3.5 | F7: 26.81 | G7: 147.48 | H7: 1434.0585 | I7: 10984.888 | J7: 60427.128 | K7: 1327.5284 | L7: 10820.996 | M7: 24903.45 | N7: =(D8-D7)/D7 -> -0.022866222 | O7: =(K8-K7)/K7 -> -0.022866222 | P7: =(L8-L7)/L7 -> -0.022126249 | Q7: =(M8-M7)/M7 -> -0.022062394
C8: Test2 | D8: 400.362 | E8: 3.5 | F8: 26.83 | G8: 147.52 | H8: 1401.267 | I8: 10741.712 | J8: 59061.402 | K8: 1297.1729 | L8: 10581.568 | M8: 24354.02
B9: O3 | C9: Test1 | D9: 21.569 | E9: 3.52 | F9: 23.76 | G9: 139.3 | H9: 75.92288 | I9: 512.47944 | J9: 3004.5617 | K9: 70.31494 | L9: 503.85184 | M9: 1134.7451 | N9: =(D10-D9)/D9 -> -0.0500255 | O9: =(K10-K9)/K9 -> -0.055853564 | P9: =(L10-L9)/L9 -> 0.077261323 | Q9: =(M10-M9)/M9 -> 0.065358212
C10: Test2 | D10: 20.49 | E10: 3.5 | F10: 26.89 | G10: 145.7 | H10: 71.715 | I10: 550.9761 | J10: 2985.393 | K10: 66.3876 | L10: 542.7801 | M10: 1208.91
A11: T07 | B11: O0 | C11: Test1 | D11: 2.094 | E11: 3.55 | F11: 15.94 | G11: 121.5 | H11: 7.4337 | I11: 33.37836 | J11: 254.421 | K11: 6.55422 | L11: 32.16384 | M11: 71.7195 | N11: =(D12-D11)/D11 -> -0.5 | O11: =(K12-K11)/K11 -> -0.48881789 | P11: =(L12-L11)/L11 -> -0.52311198 | Q11: =(M12-M11)/M11 -> -0.56175182
C12: Test2 | D12: 1.047 | E12: 3.62 | F12: 15.23 | G12: 117.27 | H12: 3.79014 | I12: 15.94581 | J12: 122.78169 | K12: 3.3504 | L12: 15.33855 | M12: 31.43094
B13: O3 | C13: Test1 | D13: 2.094 | E13: 3.55 | F13: 15.6 | G13: 119.95 | H13: 7.4337 | I13: 32.6664 | J13: 251.1753 | K13: 6.55422 | L13: 31.45188 | M13: 68.4738 | N13: =(D14-D13)/D13 -> -0.5 | O13: =(K14-K13)/K13 -> -0.48722045 | P13: =(L14-L13)/L13 -> -0.5286285 | Q13: =(M14-M13)/M13 -> -0.55764526
C14: Test2 | D14: 1.047 | E14: 3.63 | F14: 14.74 | G14: 116.19 | H14: 3.80061 | I14: 15.43278 | J14: 121.65093 | K14: 3.36087 | L14: 14.82552 | M14: 30.28971
A15: T08 | B15: O0 | C15: Test1 | D15: 4.747 | E15: 3.52 | F15: 26.91 | G15: 142.41 | H15: 16.70944 | I15: 127.74177 | J15: 676.02027 | K15: 14.7157 | L15: 124.98851 | M15: 261.13247 | N15: =(D16-D15)/D15 -> 0.45081104 | O15: =(K16-K15)/K15 -> 0.46485115 | P15: =(L16-L15)/L15 -> 0.48938178 | Q15: =(M16-M15)/M15 -> 0.53467905
C16: Test2 | D16: 6.887 | E16: 3.55 | F16: 27.61 | G16: 145.59 | H16: 24.44885 | I16: 190.15007 | J16: 1002.6783 | K16: 21.55631 | L16: 186.15561 | M16: 400.75453
B17: O3 | C17: Test1 | D17: 22.572 | E17: 3.51 | F17: 23.85 | G17: 139.73 | H17: 79.22772 | I17: 538.3422 | J17: 3153.9856 | K17: 69.74748 | L17: 525.25044 | M17: 1181.1928 | N17: =(D18-D17)/D17 -> -0.69174198 | O17: =(K18-K17)/K17 -> -0.68974678 | P17: =(L18-L17)/L17 -> -0.63742922 | Q17: =(M18-M17)/M17 -> -0.65333491
C18: Test2 | D18: 6.958 | E18: 3.53 | F18: 27.95 | G18: 146.25 | H18: 24.56174 | I18: 194.4761 | J18: 1017.6075 | K18: 21.63938 | L18: 190.44046 | M18: 409.4783
A19: T09 | B19: O0 | C19: Test1 | D19: 0.541 | E19: 3.72 | F19: 8.06 | G19: 119.19 | H19: 2.01252 | I19: 4.36046 | J19: 64.48179 | K19: 1.7853 | L19: 4.04668 | M19: 11.47461 | N19: =(D20-D19)/D19 -> -0.033271719 | O19: =(K20-K19)/K19 -> -0.030342239 | P19: =(L20-L19)/L19 -> -0.15863622 | Q19: =(M20-M19)/M19 -> -0.10072848
C20: Test2 | D20: 0.523 | E20: 3.73 | F20: 7.09 | G20: 117.7 | H20: 1.95079 | I20: 3.70807 | J20: 61.5571 | K20: 1.73113 | L20: 3.40473 | M20: 10.31879
B21: O3 | C21: Test1 | D21: 0.524 | E21: 3.73 | F21: 7.77 | G21: 118.13 | H21: 1.95452 | I21: 4.07148 | J21: 61.90012 | K21: 1.73444 | L21: 3.76756 | M21: 10.5586 | N21: =(D22-D21)/D21 -> -0.0019083969 | O21: =(K22-K21)/K21 -> -0.0049237794 | P21: =(L22-L21)/L21 -> -0.0005202306 | Q21: =(M22-M21)/M21 -> 0.0084935503
C22: Test2 | D22: 0.523 | E22: 3.72 | F22: 7.78 | G22: 118.33 | H22: 1.94556 | I22: 4.06894 | J22: 61.88659 | K22: 1.7259 | L22: 3.7656 | M22: 10.64828
A23: T10 | B23: O0 | C23: Test1 | D23: 81.871 | E23: 3.51 | F23: 28.92 | G23: 151.17 | H23: 287.36721 | I23: 2367.7093 | J23: 12376.439 | K23: 252.98139 | L23: 2320.2241 | M23: 5473.8951 | N23: =(D24-D23)/D23 -> -0.98715052 | O23: =(K24-K23)/K23 -> -0.98665151 | P23: =(L24-L23)/L23 -> -0.99654959 | Q23: =(M24-M23)/M23 -> -0.99557975
C24: Test2 | D24: 1.052 | E24: 3.63 | F24: 8.19 | G24: 107.31 | H24: 3.81876 | I24: 8.61588 | J24: 112.89012 | K24: 3.37692 | L24: 8.00572 | M24: 24.196
B25: O3 | C25: Test1 | D25: 81.566 | E25: 3.52 | F25: 28.88 | G25: 152.29 | H25: 287.11232 | I25: 2355.6261 | J25: 12421.686 | K25: 252.8546 | L25: 2308.3178 | M25: 5544.8567 | N25: =(D26-D25)/D25 -> -0.99355123 | O25: =(K26-K25)/K25 -> -0.99313519 | P25: =(L26-L25)/L25 -> -0.99856213 | Q25: =(M26-M25)/M25 -> -0.99810559
C26: Test2 | D26: 0.526 | E26: 3.72 | F26: 6.89 | G26: 104.28 | H26: 1.95672 | I26: 3.62414 | J26: 54.85128 | K26: 1.7358 | L26: 3.31906 | M26: 10.50422
A27: T11 | B27: O0 | C27: Test1 | D27: 2.095 | E27: 3.54 | F27: 17.14 | G27: 123.05 | H27: 7.4163 | I27: 35.9083 | J27: 257.78975 | K27: 6.5364 | L27: 34.6932 | M27: 79.8614 | N27: =(D28-D27)/D27 -> -0.00047732697 | O27: =(K28-K27)/K27 -> -0.0036809253 | P27: =(L28-L27)/L27 -> 0.025476462 | Q27: =(M28-M27)/M27 -> -0.001526144
C28: Test2 | D28: 2.094 | E28: 3.53 | F28: 17.57 | G28: 123 | H28: 7.39182 | I28: 36.79158 | J28: 257.562 | K28: 6.51234 | L28: 35.57706 | M28: 79.73952
B29: O3 | C29: Test1 | D29: 1.047 | E29: 3.61 | F29: 12.86 | G29: 114.3 | H29: 3.77967 | I29: 13.46442 | J29: 119.6721 | K29: 3.33993 | L29: 12.85716 | M29: 30.76086 | N29: =(D30-D29)/D29 -> 0 | O29: =(K30-K29)/K29 -> 0 | P29: =(L30-L29)/L29 -> -0.24918567 | Q29: =(M30-M29)/M29 -> -0.20762423
C30: Test2 | D30: 1.047 | E30: 3.61 | F30: 9.8 | G30: 108.2 | H30: 3.77967 | I30: 10.2606 | J30: 113.2854 | K30: 3.33993 | L30: 9.65334 | M30: 24.37416
A31: T12 | B31: O0 | C31: Test1 | D31: 1.047 | E31: 3.59 | F31: 13.32 | G31: 114.16 | H31: 3.75873 | I31: 13.94604 | J31: 119.52552 | K31: 3.31899 | L31: 13.33878 | M31: 27.38952 | N31: =(D32-D31)/D31 -> 0 | O31: =(K32-K31)/K31 -> 0.0031545741 | P31: =(L32-L31)/L31 -> -0.28492936 | Q31: =(M32-M31)/M31 -> -0.14105505
C32: Test2 | D32: 1.047 | E32: 3.6 | F32: 9.69 | G32: 110.47 | H32: 3.7692 | I32: 10.14543 | J32: 115.66209 | K32: 3.32946 | L32: 9.53817 | M32: 23.52609
B33: O3 | C33: Test1 | D33: 1.047 | E33: 3.61 | F33: 11.23 | G33: 112.08 | H33: 3.77967 | I33: 11.75781 | J33: 117.34776 | K33: 3.33993 | L33: 11.15055 | M33: 25.22223 | N33: =(D34-D33)/D33 -> -0.41642789 | O33: =(K34-K33)/K33 -> -0.39630471 | P33: =(L34-L33)/L33 -> -0.60985602 | Q33: =(M34-M33)/M33 -> -0.56419833
C34: Test2 | D34: 0.611 | E34: 3.72 | F34: 7.7 | G34: 105.98 | H34: 2.27292 | I34: 4.7047 | J34: 64.75378 | K34: 2.0163 | L34: 4.35032 | M34: 10.99189
A35: T13 | B35: O0 | C35: Test1 | D35: 8.378 | E35: 3.49 | F35: 24.17 | G35: 139.42 | H35: 29.23922 | I35: 202.49626 | J35: 1168.0608 | K35: 25.72046 | L35: 197.63702 | M35: 455.00918 | N35: =(D36-D35)/D35 -> 0.011458582 | O35: =(K36-K35)/K35 -> 0.0081639286 | P35: =(L36-L35)/L35 -> 0.014888709 | Q35: =(M36-M35)/M35 -> -0.0062340281
C36: Test2 | D36: 8.474 | E36: 3.48 | F36: 24.25 | G36: 138.47 | H36: 29.48952 | I36: 205.4945 | J36: 1173.3948 | K36: 25.93044 | L36: 200.57958 | M36: 452.17264
B37: O3 | C37: Test1 | D37: 6.283 | E37: 3.49 | F37: 23.14 | G37: 137.16 | H37: 21.92767 | I37: 145.38862 | J37: 861.77628 | K37: 19.28881 | L37: 141.74448 | M37: 327.09298 | N37: =(D38-D37)/D37 -> 0.0039789909 | O37: =(K38-K37)/K37 -> 0.00070870106 | P37: =(L38-L37)/L37 -> -0.069005297 | Q37: =(M38-M37)/M37 -> -0.084732176
C38: Test2 | D38: 6.308 | E38: 3.48 | F38: 21.5 | G38: 132.57 | H38: 21.95184 | I38: 135.622 | J38: 836.25156 | K38: 19.30248 | L38: 131.96336 | M38: 299.37768
A39: T16 | B39: O0 | C39: Test1 | D39: 1.047 | E39: 3.57 | F39: 10.62 | G39: 112.06 | H39: 3.73779 | I39: 11.11914 | J39: 117.32682 | K39: 3.29805 | L39: 10.51188 | M39: 24.26946 | N39: =(D40-D39)/D39 -> 0 | O39: =(K40-K39)/K39 -> 0.0063492063 | P39: =(L40-L39)/L39 -> -0.071713147 | Q39: =(M40-M39)/M39 -> -0.082830026
C40: Test2 | D40: 1.047 | E40: 3.59 | F40: 9.9 | G40: 110.14 | H40: 3.75873 | I40: 10.3653 | J40: 115.31658 | K40: 3.31899 | L40: 9.75804 | M40: 22.25922
...

Sheet C Impact of Optimization
A1: Technique | B1: Test | C1: Optimization | D1: Time (s) | E1: Power | H1: Consumption (with baseline) | K1: Consumption (without baseline) | N1: Impact of Optimization (O3-O0)/O0%
E2: HDD (w) | F2: CPU (w) | G2: DUT (w) | H2: HDD (J) | I2: CPU (J) | J2: DUT (J) | K2: HDD (J) | L2: CPU (J) | M2: DUT (J) | N2: Time (s) | O2: HDD (J) | P2: CPU (J) | Q2: DUT (J)
A3: T04 | B3: Test1 | C3: O0 | D3: 4.713 | E3: 3.48 | F3: 22.78 | G3: 132.94 | H3: 16.40124 | I3: 107.36214 | J3: 626.54622 | K3: 14.42178 | L3: 104.6286 | M3: 242.2482 | N3: =(D4-D3)/D3 -> -0.34839805 | O3: =(K4-K3)/K3 -> -0.34200979 | P3: =(L4-L3)/L3 -> -0.43880048 | Q3: =(M4-M3)/M3 -> -0.42826366
C4: O3 | D4: 3.071 | E4: 3.51 | F4: 19.7 | G4: 126.64 | H4: 10.77921 | I4: 60.4987 | J4: 388.91144 | K4: 9.48939 | L4: 58.71752 | M4: 138.5021
B5: Test2 | C5: O0 | D5: 3.665 | E5: 3.5 | F5: 19.79 | G5: 126.47 | H5: 12.8275 | I5: 72.53035 | J5: 463.51255 | K5: 11.2882 | L5: 70.40465 | M5: 164.66845 | N5: =(D6-D5)/D5 -> -0.71405184 | O5: =(K6-K5)/K5 -> -0.70662462 | P5: =(L6-L5)/L5 -> -0.83358145 | Q5: =(M6-M5)/M5 -> -0.80703432
C6: O3 | D6: 1.048 | E6: 3.58 | F6: 11.76 | G6: 111.86 | H6: 3.75184 | I6: 12.32448 | J6: 117.22928 | K6: 3.31168 | L6: 11.71664 | M6: 31.77536
A7: T05 | B7: Test1 | C7: O0 | D7: 409.731 | E7: 3.5 | F7: 26.81 | G7: 147.48 | H7: 1434.0585 | I7: 10984.888 | J7: 60427.128 | K7: 1327.5284 | L7: 10820.996 | M7: 24903.45 | N7: =(D8-D7)/D7 -> -0.94735814 | O7: =(K8-K7)/K7 -> -0.9470332 | P7: =(L8-L7)/L7 -> -0.95343757 | Q7: =(M8-M7)/M7 -> -0.95443422
C8: O3 | D8: 21.569 | E8: 3.52 | F8: 23.76 | G8: 139.3 | H8: 75.92288 | I8: 512.47944 | J8: 3004.5617 | K8: 70.31494 | L8: 503.85184 | M8: 1134.7451
B9: Test2 | C9: O0 | D9: 400.362 | E9: 3.5 | F9: 26.83 | G9: 147.52 | H9: 1401.267 | I9: 10741.712 | J9: 59061.402 | K9: 1297.1729 | L9: 10581.568 | M9: 24354.02 | N9: =(D10-D9)/D9 -> -0.94882132 | O9: =(K10-K9)/K9 -> -0.94882132 | P9: =(L10-L9)/L9 -> -0.94870513 | Q9: =(M10-M9)/M9 -> -0.95036097
C10: O3 | D10: 20.49 | E10: 3.5 | F10: 26.89 | G10: 145.7 | H10: 71.715 | I10: 550.9761 | J10: 2985.393 | K10: 66.3876 | L10: 542.7801 | M10: 1208.91
A11: T07 | B11: Test1 | C11: O0 | D11: 2.094 | E11: 3.55 | F11: 15.94 | G11: 121.5 | H11: 7.4337 | I11: 33.37836 | J11: 254.421 | K11: 6.55422 | L11: 32.16384 | M11: 71.7195 | N11: =(D12-D11)/D11 -> 0 | O11: =(K12-K11)/K11 -> 0 | P11: =(L12-L11)/L11 -> -0.022135417 | Q11: =(M12-M11)/M11 -> -0.045255474
C12: O3 | D12: 2.094 | E12: 3.55 | F12: 15.6 | G12: 119.95 | H12: 7.4337 | I12: 32.6664 | J12: 251.1753 | K12: 6.55422 | L12: 31.45188 | M12: 68.4738
B13: Test2 | C13: O0 | D13: 1.047 | E13: 3.62 | F13: 15.23 | G13: 117.27 | H13: 3.79014 | I13: 15.94581 | J13: 122.78169 | K13: 3.3504 | L13: 15.33855 | M13: 31.43094 | N13: =(D14-D13)/D13 -> 0 | O13: =(K14-K13)/K13 -> 0.003125 | P13: =(L14-L13)/L13 -> -0.033447099 | Q13: =(M14-M13)/M13 -> -0.036309127
C14: O3 | D14: 1.047 | E14: 3.63 | F14: 14.74 | G14: 116.19 | H14: 3.80061 | I14: 15.43278 | J14: 121.65093 | K14: 3.36087 | L14: 14.82552 | M14: 30.28971
A15: T08 | B15: Test1 | C15: O0 | D15: 4.747 | E15: 3.52 | F15: 26.91 | G15: 142.41 | H15: 16.70944 | I15: 127.74177 | J15: 676.02027 | K15: 14.7157 | L15: 124.98851 | M15: 261.13247 | N15: =(D16-D15)/D15 -> 3.7550032 | O15: =(K16-K15)/K15 -> 3.7396644 | P15: =(L16-L15)/L15 -> 3.2023898 | Q15: =(M16-M15)/M15 -> 3.5233469
C16: O3 | D16: 22.572 | E16: 3.51 | F16: 23.85 | G16: 139.73 | H16: 79.22772 | I16: 538.3422 | J16: 3153.9856 | K16: 69.74748 | L16: 525.25044 | M16: 1181.1928
B17: Test2 | C17: O0 | D17: 6.887 | E17: 3.55 | F17: 27.61 | G17: 145.59 | H17: 24.44885 | I17: 190.15007 | J17: 1002.6783 | K17: 21.55631 | L17: 186.15561 | M17: 400.75453 | N17: =(D18-D17)/D17 -> 0.010309278 | O17: =(K18-K17)/K17 -> 0.003853628 | P17: =(L18-L17)/L17 -> 0.023017571 | Q17: =(M18-M17)/M17 -> 0.021768363
C18: O3 | D18: 6.958 | E18: 3.53 | F18: 27.95 | G18: 146.25 | H18: 24.56174 | I18: 194.4761 | J18: 1017.6075 | K18: 21.63938 | L18: 190.44046 | M18: 409.4783
A19: T09 | B19: Test1 | C19: O0 | D19: 0.541 | E19: 3.72 | F19: 8.06 | G19: 119.19 | H19: 2.01252 | I19: 4.36046 | J19: 64.48179 | K19: 1.7853 | L19: 4.04668 | M19: 11.47461 | N19: =(D20-D19)/D19 -> -0.03142329 | O19: =(K20-K19)/K19 -> -0.028488209 | P19: =(L20-L19)/L19 -> -0.068975061 | Q19: =(M20-M19)/M19 -> -0.079829293
C20: O3 | D20: 0.524 | E20: 3.73 | F20: 7.77 | G20: 118.13 | H20: 1.95452 | I20: 4.07148 | J20: 61.90012 | K20: 1.73444 | L20: 3.76756 | M20: 10.5586
B21: Test2 | C21: O0 | D21: 0.523 | E21: 3.73 | F21: 7.09 | G21: 117.7 | H21: 1.95079 | I21: 3.70807 | J21: 61.5571 | K21: 1.73113 | L21: 3.40473 | M21: 10.31879 | N21: =(D22-D21)/D21 -> 0 | O21: =(K22-K21)/K21 -> -0.003021148 | P21: =(L22-L21)/L21 -> 0.10599078 | Q21: =(M22-M21)/M21 -> 0.031931069
C22: O3 | D22: 0.523 | E22: 3.72 | F22: 7.78 | G22: 118.33 | H22: 1.94556 | I22: 4.06894 | J22: 61.88659 | K22: 1.7259 | L22: 3.7656 | M22: 10.64828
A23: T10 | B23: Test1 | C23: O0 | D23: 81.871 | E23: 3.51 | F23: 28.92 | G23: 151.17 | H23: 287.36721 | I23: 2367.7093 | J23: 12376.439 | K23: 252.98139 | L23: 2320.2241 | M23: 5473.8951 | N23: =(D24-D23)/D23 -> -0.0037253728 | O23: =(K24-K23)/K23 -> -0.00050118311 | P23: =(L24-L23)/L23 -> -0.0051315473 | Q23: =(M24-M23)/M23 -> 0.012963643
C24: O3 | D24: 81.566 | E24: 3.52 | F24: 28.88 | G24: 152.29 | H24: 287.11232 | I24: 2355.6261 | J24: 12421.686 | K24: 252.8546 | L24: 2308.3178 | M24: 5544.8567
B25: Test2 | C25: O0 | D25: 1.052 | E25: 3.63 | F25: 8.19 | G25: 107.31 | H25: 3.81876 | I25: 8.61588 | J25: 112.89012 | K25: 3.37692 | L25: 8.00572 | M25: 24.196 | N25: =(D26-D25)/D25 -> -0.5 | O25: =(K26-K25)/K25 -> -0.48598131 | P25: =(L26-L25)/L25 -> -0.58541393 | Q25: =(M26-M25)/M25 -> -0.56586957
C26: O3 | D26: 0.526 | E26: 3.72 | F26: 6.89 | G26: 104.28 | H26: 1.95672 | I26: 3.62414 | J26: 54.85128 | K26: 1.7358 | L26: 3.31906 | M26: 10.50422
A27: T11 | B27: Test1 | C27: O0 | D27: 2.095 | E27: 3.54 | F27: 17.14 | G27: 123.05 | H27: 7.4163 | I27: 35.9083 | J27: 257.78975 | K27: 6.5364 | L27: 34.6932 | M27: 79.8614 | N27: =(D28-D27)/D27 -> -0.50023866 | O27: =(K28-K27)/K27 -> -0.48902607 | P27: =(L28-L27)/L27 -> -0.62940403 | Q27: =(M28-M27)/M27 -> -0.61482193
C28: O3 | D28: 1.047 | E28: 3.61 | F28: 12.86 | G28: 114.3 | H28: 3.77967 | I28: 13.46442 | J28: 119.6721 | K28: 3.33993 | L28: 12.85716 | M28: 30.76086
B29: Test2 | C29: O0 | D29: 2.094 | E29: 3.53 | F29: 17.57 | G29: 123 | H29: 7.39182 | I29: 36.79158 | J29: 257.562 | K29: 6.51234 | L29: 35.57706 | M29: 79.73952 | N29: =(D30-D29)/D29 -> -0.5 | O29: =(K30-K29)/K29 -> -0.48713826 | P29: =(L30-L29)/L29 -> -0.72866392 | Q29: =(M30-M29)/M29 -> -0.69432773
C30: O3 | D30: 1.047 | E30: 3.61 | F30: 9.8 | G30: 108.2 | H30: 3.77967 | I30: 10.2606 | J30: 113.2854 | K30: 3.33993 | L30: 9.65334 | M30: 24.37416
A31: T12 | B31: Test1 | C31: O0 | D31: 1.047 | E31: 3.59 | F31: 13.32 | G31: 114.16 | H31: 3.75873 | I31: 13.94604 | J31: 119.52552 | K31: 3.31899 | L31: 13.33878 | M31: 27.38952 | N31: =(D32-D31)/D31 -> 0 | O31: =(K32-K31)/K31 -> 0.0063091483 | P31: =(L32-L31)/L31 -> -0.16405024 | Q31: =(M32-M31)/M31 -> -0.07912844
C32: O3 | D32: 1.047 | E32: 3.61 | F32: 11.23 | G32: 112.08 | H32: 3.77967 | I32: 11.75781 | J32: 117.34776 | K32: 3.33993 | L32: 11.15055 | M32: 25.22223
B33: Test2 | C33: O0 | D33: 1.047 | E33: 3.6 | F33: 9.69 | G33: 110.47 | H33: 3.7692 | I33: 10.14543 | J33: 115.66209 | K33: 3.32946 | L33: 9.53817 | M33: 23.52609 | N33: =(D34-D33)/D33 -> -0.41642789 | O33: =(K34-K33)/K33 -> -0.3944063 | P33: =(L34-L33)/L33 -> -0.54390412 | Q33: =(M34-M33)/M33 -> -0.53277872
C34: O3 | D34: 0.611 | E34: 3.72 | F34: 7.7 | G34: 105.98 | H34: 2.27292 | I34: 4.7047 | J34: 64.75378 | K34: 2.0163 | L34: 4.35032 | M34: 10.99189
A35: T13 | B35: Test1 | C35: O0 | D35: 8.378 | E35: 3.49 | F35: 24.17 | G35: 139.42 | H35: 29.23922 | I35: 202.49626 | J35: 1168.0608 | K35: 25.72046 | L35: 197.63702 | M35: 455.00918 | N35: =(D36-D35)/D35 -> -0.25005968 | O35: =(K36-K35)/K35 -> -0.25005968 | P35: =(L36-L35)/L35 -> -0.282804 | Q35: =(M36-M35)/M35 -> -0.28112883
C36: O3 | D36: 6.283 | E36: 3.49 | F36: 23.14 | G36: 137.16 | H36: 21.92767 | I36: 145.38862 | J36: 861.77628 | K36: 19.28881 | L36: 141.74448 | M36: 327.09298
B37: Test2 | C37: O0 | D37: 8.474 | E37: 3.48 | F37: 24.25 | G37: 138.47 | H37: 29.48952 | I37: 205.4945 | J37: 1173.3948 | K37: 25.93044 | L37: 200.57958 | M37: 452.17264 | N37: =(D38-D37)/D37 -> -0.25560538 | O37: =(K38-K37)/K37 -> -0.25560538 | P37: =(L38-L37)/L37 -> -0.34208976 | Q37: =(M38-M37)/M37 -> -0.33791288
C38: O3 | D38: 6.308 | E38: 3.48 | F38: 21.5 | G38: 132.57 | H38: 21.95184 | I38: 135.622 | J38: 836.25156 | K38: 19.30248 | L38: 131.96336 | M38: 299.37768
A39: T16 | B39: Test1 | C39: O0 | D39: 1.047 | E39: 3.57 | F39: 10.62 | G39: 112.06 | H39: 3.73779 | I39: 11.11914 | J39: 117.32682 | K39: 3.29805 | L39: 10.51188 | M39: 24.26946 | N39: =(D40-D39)/D39 -> 0 | O39: =(K40-K39)/K39 -> 0.0095238095 | P39: =(L40-L39)/L39 -> 0.00099601594 | Q39: =(M40-M39)/M39 -> -0.029335634
C40: O3 | D40: 1.047 | E40: 3.6 | F40: 10.63 | G40: 111.38 | H40: 3.7692 | I40: 11.12961 | J40: 116.61486 | K40: 3.32946 | L40: 10.52235 | M40: 23.5575
...

Sheet C Technique results
C2: Optimization level O0 | N2: Optimization level O3
C3: Time (s) | H3: Energy consumption (J) | N3: Time (s) | S3: Energy consumption (J) | Z3: Energy consumption (J) | AC3: Energy consumption (J)
B4: Technique | C4: Optimization level O0 | D4: Optimization level O3 | E4: Impact (%) | F4: p-value | G4: Effect size | H4: Optimization level O0 | I4: Optimization level O3 | J4: Impact (%) | K4: p-value | L4: Effect size | M4: Technique | N4: Optimization level O0 | O4: Optimization level O3 | P4: Impact (%) | Q4: p-value | R4: Effect size | S4: Optimization level O0 | T4: Optimization level O3 | U4: Impact (%) | V4: p-value | W4: Effect size | X4: Average impact (%) | Z4: Optimization level O0 | AC4: Optimization level O3
B5: T4 | C5: {=INDIRECT("'C Impact of Technique'!D" & 3 + (ROW(A1)-1)*4)} -> 4.713 | D5: {=INDIRECT("'C Impact of Technique'!D" & 4 + (ROW(A1)-1)*4)} -> 3.665 | E5: {=INDIRECT("'C Impact of Technique'!N" & 3 + (ROW(A1)-1)*4)*100} -> -22.236367 | F5: 2.8719491e-11 | G5: large | H5: {=INDIRECT("'C Impact of Technique'!M" & 3 + (ROW(A1)-1)*4)} -> 242.2482 | I5: {=INDIRECT("'C Impact of Technique'!M" & 4 + (ROW(A1)-1)*4)} -> 164.66845 | J5: {=INDIRECT("'C Impact of Technique'!Q" & 3 + (ROW(A1)-1)*4)*100} -> -32.024903 | K5: 2.8719491e-11 | L5: large | M5: T4 | N5: {=INDIRECT("'C Impact of Technique'!D" & 5 + (ROW(A1)-1)*4)} -> 3.071 | O5: {=INDIRECT("'C Impact of Technique'!D" & 6 + (ROW(A1)-1)*4)} -> 1.048 | P5: {=INDIRECT("'C Impact of Technique'!N" & 5 + (ROW(A1)-1)*4)*100} -> -65.874308 | Q5: 2.8719491e-11 | R5: large | S5: {=INDIRECT("'C Impact of Technique'!M" & 5 + (ROW(A1)-1)*4)} -> 138.5021 | T5: {=INDIRECT("'C Impact of Technique'!M" & 6 + (ROW(A1)-1)*4)} -> 31.77536 | U5: {=INDIRECT("'C Impact of Technique'!Q" & 5 + (ROW(A1)-1)*4)*100} -> -77.05785 | V5: 2.8719491e-11 | W5: large | X5: =AVERAGE(J5,U5) -> -54.541376 | Z5: Impact | AA5: Techniques | AC5: Impact | AD5: Techniques
B6: T5 | C6: {=INDIRECT("'C Impact of Technique'!D" & 3 + (ROW(A2)-1)*4)} -> 409.731 | D6: {=INDIRECT("'C Impact of Technique'!D" & 4 + (ROW(A2)-1)*4)} -> 400.362 | E6: {=INDIRECT("'C Impact of Technique'!N" & 3 + (ROW(A2)-1)*4)*100} -> -2.2866222 | F6: 2.487874e-10 | G6: large | H6: {=INDIRECT("'C Impact of Technique'!M" & 3 + (ROW(A2)-1)*4)} -> 24903.45 | I6: {=INDIRECT("'C Impact of Technique'!M" & 4 + (ROW(A2)-1)*4)} -> 24354.02 | J6: {=INDIRECT("'C Impact of Technique'!Q" & 3 + (ROW(A2)-1)*4)*100} -> -2.2062394 | K6: 9.84531e-06 | L6: large | M6: T5 | N6: {=INDIRECT("'C Impact of Technique'!D" & 5 + (ROW(A2)-1)*4)} -> 21.569 | O6: {=INDIRECT("'C Impact of Technique'!D" & 6 + (ROW(A2)-1)*4)} -> 20.49 | P6: {=INDIRECT("'C Impact of Technique'!N" & 5 + (ROW(A2)-1)*4)*100} -> -5.00255 | Q6: 2.8719491e-11 | R6: large | S6: {=INDIRECT("'C Impact of Technique'!M" & 5 + (ROW(A2)-1)*4)} -> 1134.7451 | T6: {=INDIRECT("'C Impact of Technique'!M" & 6 + (ROW(A2)-1)*4)} -> 1208.91 | U6: {=INDIRECT("'C Impact of Technique'!Q" & 5 + (ROW(A2)-1)*4)*100} -> 6.5358212 | V6: 2.8719491e-11 | W6: large | X6: =AVERAGE(J6,U6) -> 2.1647909 | Z6: <= -75 | AA6: {=_xlfn.TEXTJOIN(", ", TRUE, IF(J5:J30 <= -75, B5:B30, ""))} -> T10 | AC6: <= -75 | AD6: {=_xlfn.TEXTJOIN(", ", TRUE, IF(U5:U30 <= -75, M5:M30, ""))} -> T4, T10, T26, T40
B7: T7 | C7: {=INDIRECT("'C Impact of Technique'!D" & 3 + (ROW(A3)-1)*4)} -> 2.094 | D7: {=INDIRECT("'C Impact of Technique'!D" & 4 + (ROW(A3)-1)*4)} -> 1.047 | E7: {=INDIRECT("'C Impact of Technique'!N" & 3 + (ROW(A3)-1)*4)*100} -> -50 | F7: 2.8719491e-11 | G7: large | H7: {=INDIRECT("'C Impact of Technique'!M" & 3 + (ROW(A3)-1)*4)} -> 71.7195 | I7: {=INDIRECT("'C Impact of Technique'!M" & 4 + (ROW(A3)-1)*4)} -> 31.43094 | J7: {=INDIRECT("'C Impact of Technique'!Q" & 3 + (ROW(A3)-1)*4)*100} -> -56.175182 | K7: 2.8719491e-11 | L7: large | M7: T7 | N7: {=INDIRECT("'C Impact of Technique'!D" & 5 + (ROW(A3)-1)*4)} -> 2.094 | O7: {=INDIRECT("'C Impact of Technique'!D" & 6 + (ROW(A3)-1)*4)} -> 1.047 | P7: {=INDIRECT("'C Impact of Technique'!N" & 5 + (ROW(A3)-1)*4)*100} -> -50 | Q7: 2.8719491e-11 | R7: large | S7: {=INDIRECT("'C Impact of Technique'!M" & 5 + (ROW(A3)-1)*4)} -> 68.4738 | T7: {=INDIRECT("'C Impact of Technique'!M" & 6 + (ROW(A3)-1)*4)} -> 30.28971 | U7: {=INDIRECT("'C Impact of Technique'!Q" & 5 + (ROW(A3)-1)*4)*100} -> -55.764526 | V7: 2.8719491e-11 | W7: large | X7: =AVERAGE(J7,U7) -> -55.969854 | Z7: > -75 & <= -25 | AA7: {=_xlfn.TEXTJOIN(", ", TRUE, IF((J5:J30 > -75) * (J5:J30 <= -25), B5:B30, ""))} -> T4, T7, T20, T50, T51 | AC7: > -75 & <= -25 | AD7: {=_xlfn.TEXTJOIN(", ", TRUE, IF((U5:U30 > -75) * (U5:U30 <= -25), M5:M30, ""))} -> T7, T8, T12, T51
B8: T8 | C8: {=INDIRECT("'C Impact of Technique'!D" & 3 + (ROW(A4)-1)*4)} -> 4.747 | D8: {=INDIRECT("'C Impact of Technique'!D" & 4 + (ROW(A4)-1)*4)} -> 6.887 | E8: {=INDIRECT("'C Impact of Technique'!N" & 3 + (ROW(A4)-1)*4)*100} -> 45.081104 | F8: 2.8719491e-11 | G8: large | H8: {=INDIRECT("'C Impact of Technique'!M" & 3 + (ROW(A4)-1)*4)} -> 261.13247 | I8: {=INDIRECT("'C Impact of Technique'!M" & 4 + (ROW(A4)-1)*4)} -> 400.75453 | J8: {=INDIRECT("'C Impact of Technique'!Q" & 3 + (ROW(A4)-1)*4)*100} -> 53.467905 | K8: 2.8719491e-11 | L8: large | M8: T8 | N8: {=INDIRECT("'C Impact of Technique'!D" & 5 + (ROW(A4)-1)*4)} -> 22.572 | O8: {=INDIRECT("'C Impact of Technique'!D" & 6 + (ROW(A4)-1)*4)} -> 6.958 | P8: {=INDIRECT("'C Impact of Technique'!N" & 5 + (ROW(A4)-1)*4)*100} -> -69.174198 | Q8: 2.8719491e-11 | R8: large | S8: {=INDIRECT("'C Impact of Technique'!M" & 5 + (ROW(A4)-1)*4)} -> 1181.1928 | T8: {=INDIRECT("'C Impact of Technique'!M" & 6 + (ROW(A4)-1)*4)} -> 409.4783 | U8: {=INDIRECT("'C Impact of Technique'!Q" & 5 + (ROW(A4)-1)*4)*100} -> -65.333491 | V8: 2.8719491e-11 | W8: large | X8: =AVERAGE(J8,U8) -> -5.932793 | Z8: > -25 & <= -3 | AA8: {=_xlfn.TEXTJOIN(", ", TRUE, IF((J5:J30 > -25) * (J5:J30 <= -3), B5:B30, ""))} -> T9, T12, T16, T25, T40, T49 | AC8: > -25 & <= -3 | AD8: {=_xlfn.TEXTJOIN(", ", TRUE, IF((U5:U30 > -25) * (U5:U30 <= -3), M5:M30, ""))} -> T11, T13, T16, T25, T44, T50
B9: T9 | C9: {=INDIRECT("'C Impact of Technique'!D" & 3 + (ROW(A5)-1)*4)} -> 0.541 | D9: {=INDIRECT("'C Impact of Technique'!D" & 4 + (ROW(A5)-1)*4)} -> 0.523 | E9: {=INDIRECT("'C Impact of Technique'!N" & 3 + (ROW(A5)-1)*4)*100} -> -3.3271719 | F9: 0.75058723 | G9: null hypothesis cannot be rejected | H9: {=INDIRECT("'C Impact of Technique'!M" & 3 + (ROW(A5)-1)*4)} -> 11.47461 | I9: {=INDIRECT("'C Impact of Technique'!M" & 4 + (ROW(A5)-1)*4)} -> 10.31879 | J9: {=INDIRECT("'C Impact of Technique'!Q" & 3 + (ROW(A5)-1)*4)*100} -> -10.072848 | K9: 0.0028223336 | L9: medium | M9: T9 | N9: {=INDIRECT("'C Impact of Technique'!D" & 5 + (ROW(A5)-1)*4)} -> 0.524 | O9: {=INDIRECT("'C Impact of Technique'!D" & 6 + (ROW(A5)-1)*4)} -> 0.523 | P9: {=INDIRECT("'C Impact of Technique'!N" & 5 + (ROW(A5)-1)*4)*100} -> -0.19083969 | Q9: 0.23984999 | R9: null hypothesis cannot be rejected | S9: {=INDIRECT("'C Impact of Technique'!M" & 5 + (ROW(A5)-1)*4)} -> 10.5586 | T9: {=INDIRECT("'C Impact of Technique'!M" & 6 + (ROW(A5)-1)*4)} -> 10.64828 | U9: {=INDIRECT("'C Impact of Technique'!Q" & 5 + (ROW(A5)-1)*4)*100} -> 0.84935503 | V9: 0.88246568 | W9: small | X9: =AVERAGE(J9,U9) -> -4.6117464 | Z9: > -3 & < 3 | AA9: {=_xlfn.TEXTJOIN(", ", TRUE, IF((J5:J30 > -3) * (J5:J30 < 3), B5:B30, ""))} -> T5, T11, T13, T17, T26, T29, T32, T33, T44 | AC9: > -3 & < 3 | AD9: {=_xlfn.TEXTJOIN(", ", TRUE, IF((U5:U30 > -3) * (U5:U30 < 3), M5:M30, ""))} -> T9, T17, T29, T32, T36
B10: T10 | C10: {=INDIRECT("'C Impact of Technique'!D" & 3 + (ROW(A6)-1)*4)} -> 81.871 | D10: {=INDIRECT("'C Impact of Technique'!D" & 4 + (ROW(A6)-1)*4)} -> 1.052 | E10: {=INDIRECT("'C Impact of Technique'!N" & 3 + (ROW(A6)-1)*4)*100} -> -98.715052 | F10: 2.8719491e-11 | G10: large | H10: {=INDIRECT("'C Impact of Technique'!M" & 3 + (ROW(A6)-1)*4)} -> 5473.8951 | I10: {=INDIRECT("'C Impact of Technique'!M" & 4 + (ROW(A6)-1)*4)} -> 24.196 | J10: {=INDIRECT("'C Impact of Technique'!Q" & 3 + (ROW(A6)-1)*4)*100} -> -99.557975 | K10: 2.8719491e-11 | L10: large | M10: T10 | N10: {=INDIRECT("'C Impact of Technique'!D" & 5 + (ROW(A6)-1)*4)} -> 81.566 | O10: {=INDIRECT("'C Impact of Technique'!D" & 6 + (ROW(A6)-1)*4)} -> 0.526 | P10: {=INDIRECT("'C Impact of Technique'!N" & 5 + (ROW(A6)-1)*4)*100} -> -99.355123 | Q10: 2.8719491e-11 | R10: large | S10: {=INDIRECT("'C Impact of Technique'!M" & 5 + (ROW(A6)-1)*4)} -> 5544.8567 | T10: {=INDIRECT("'C Impact of Technique'!M" & 6 + (ROW(A6)-1)*4)} -> 10.50422 | U10: {=INDIRECT("'C Impact of Technique'!Q" & 5 + (ROW(A6)-1)*4)*100} -> -99.810559 | V10: 2.8719491e-11 | W10: large | X10: =AVERAGE(J10,U10) -> -99.684267 | Z10: >= 3 & < 25 | AA10: {=_xlfn.TEXTJOIN(", ", TRUE, IF((J5:J30 >= 3) * (J5:J30 < 25), B5:B30, ""))} -> T19, T36 | AC10: >= 3 & < 25 | AD10: {=_xlfn.TEXTJOIN(", ", TRUE, IF((U5:U30 >= 3) * (U5:U30 < 25), M5:M30, ""))} -> T5, T19, T28, T33
B11: T11 | C11: {=INDIRECT("'C Impact of Technique'!D" & 3 + (ROW(A7)-1)*4)} -> 2.095 | D11: {=INDIRECT("'C Impact of Technique'!D" & 4 + (ROW(A7)-1)*4)} -> 2.094 | E11: {=INDIRECT("'C Impact of Technique'!N" & 3 + (ROW(A7)-1)*4)*100} -> -0.047732697 | F11: 0.16237502 | G11: null hypothesis cannot be rejected | H11: {=INDIRECT("'C Impact of Technique'!M" & 3 + (ROW(A7)-1)*4)} -> 79.8614 | I11: {=INDIRECT("'C Impact of Technique'!M" & 4 + (ROW(A7)-1)*4)} -> 79.73952 | J11: {=INDIRECT("'C Impact of Technique'!Q" & 3 + (ROW(A7)-1)*4)*100} -> -0.1526144 | K11: 0.70617149 | L11: null hypothesis cannot be rejected | M11: T11 | N11: {=INDIRECT("'C Impact of Technique'!D" & 5 + (ROW(A7)-1)*4)} -> 1.047 | O11: {=INDIRECT("'C Impact of Technique'!D" & 6 + (ROW(A7)-1)*4)} -> 1.047 | P11: {=INDIRECT("'C Impact of Technique'!N" & 5 + (ROW(A7)-1)*4)*100} -> 0 | Q11: 0.89414606 | R11: null hypothesis cannot be rejected | S11: {=INDIRECT("'C Impact of Technique'!M" & 5 + (ROW(A7)-1)*4)} -> 30.76086 | T11: {=INDIRECT("'C Impact of Technique'!M" & 6 + (ROW(A7)-1)*4)} -> 24.37416 | U11: {=INDIRECT("'C Impact of Technique'!Q" & 5 + (ROW(A7)-1)*4)*100} -> -20.762423 | V11: 4.7340207e-11 | W11: null hypothesis cannot be rejected | X11: =AVERAGE(J11,U11) -> -10.457519 | Z11: >= 25 & < 75 | AA11: {=_xlfn.TEXTJOIN(", ", TRUE, IF((J5:J30 >= 25) * (J5:J30 < 75), B5:B30, ""))} -> T8, T28, T31 | AC11: >= 25 & < 75 | AD11: {=_xlfn.TEXTJOIN(", ", TRUE, IF((U5:U30 >= 25) * (U5:U30 < 75), M5:M30, ""))} -> T20, T31
B12: T12 | C12: {=INDIRECT("'C Impact of Technique'!D" & 3 + (ROW(A8)-1)*4)} -> 1.047 | D12: {=INDIRECT("'C Impact of Technique'!D" & 4 + (ROW(A8)-1)*4)} -> 1.047 | E12: {=INDIRECT("'C Impact of Technique'!N" & 3 + (ROW(A8)-1)*4)*100} -> 0 | F12: 0.88246568 | G12: null hypothesis cannot be rejected | H12: {=INDIRECT("'C Impact of Technique'!M" & 3 + (ROW(A8)-1)*4)} -> 27.38952 | I12: {=INDIRECT("'C Impact of Technique'!M" & 4 + (ROW(A8)-1)*4)} -> 23.52609 | J12: {=INDIRECT("'C Impact of Technique'!Q" & 3 + (ROW(A8)-1)*4)*100} -> -14.105505 | K12: 1.613225e-10 | L12: large | M12: T12 | N12: {=INDIRECT("'C Impact of Technique'!D" & 5 + (ROW(A8)-1)*4)} -> 1.047 | O12: {=INDIRECT("'C Impact of Technique'!D" & 6 + (ROW(A8)-1)*4)} -> 0.611 | P12: {=INDIRECT("'C Impact of Technique'!N" & 5 + (ROW(A8)-1)*4)*100} -> -41.642789 | Q12: 2.3306153e-09 | R12: null hypothesis cannot be rejected | S12: {=INDIRECT("'C Impact of Technique'!M" & 5 + (ROW(A8)-1)*4)} -> 25.22223 | T12: {=INDIRECT("'C Impact of Technique'!M" & 6 + (ROW(A8)-1)*4)} -> 10.99189 | U12: {=INDIRECT("'C Impact of Technique'!Q" & 5 + (ROW(A8)-1)*4)*100} -> -56.419833 | V12: 2.8719491e-11 | W12: large | X12: =AVERAGE(J12,U12) -> -35.262669 | Z12: >= 75 | AA12: {=_xlfn.TEXTJOIN(", ", TRUE, IF(J5:J30 >= 75, B5:B30, ""))} | AC12: >= 75 | AD12: {=_xlfn.TEXTJOIN(", ", TRUE, IF(U5:U30 >= 75, M5:M30, ""))} -> T49
B13: T13 | C13: {=INDIRECT("'C Impact of Technique'!D" & 3 + (ROW(A9)-1)*4)} -> 8.378 | D13: {=INDIRECT("'C Impact of Technique'!D" & 4 + (ROW(A9)-1)*4)} -> 8.474 | E13: {=INDIRECT("'C Impact of Technique'!N" & 3 + (ROW(A9)-1)*4)*100} -> 1.1458582 | F13: 3.4971115e-09 | G13: large | H13: {=INDIRECT("'C Impact of Technique'!M" & 3 + (ROW(A9)-1)*4)} -> 455.00918 | I13: {=INDIRECT("'C Impact of Technique'!M" & 4 + (ROW(A9)-1)*4)} -> 452.17264 | J13: {=INDIRECT("'C Impact of Technique'!Q" & 3 + (ROW(A9)-1)*4)*100} -> -0.62340281 | K13: 0.089091634 | L13: null hypothesis cannot be rejected | M13: T13 | N13: {=INDIRECT("'C Impact of Technique'!D" & 5 + (ROW(A9)-1)*4)} -> 6.283 | O13: {=INDIRECT("'C Impact of Technique'!D" & 6 + (ROW(A9)-1)*4)} -> 6.308 | P13: {=INDIRECT("'C Impact of Technique'!N" & 5 + (ROW(A9)-1)*4)*100} -> 0.39789909 | Q13: 2.8719491e-11 | R13: large | S13: {=INDIRECT("'C Impact of Technique'!M" & 5 + (ROW(A9)-1)*4)} -> 327.09298 | T13: {=INDIRECT("'C Impact of Technique'!M" & 6 + (ROW(A9)-1)*4)} -> 299.37768 | U13: {=INDIRECT("'C Impact of Technique'!Q" & 5 + (ROW(A9)-1)*4)*100} -> -8.4732176 | V13: 2.8719491e-11 | W13: null hypothesis cannot be rejected | X13: =AVERAGE(J13,U13) -> -4.5483102
B14: T16 | C14: {=INDIRECT("'C Impact of Technique'!D" & 3 + (ROW(A10)-1)*4)} -> 1.047 | D14: {=INDIRECT("'C Impact of Technique'!D" & 4 + (ROW(A10)-1)*4)} -> 1.047 | E14: {=INDIRECT("'C Impact of Technique'!N" & 3 + (ROW(A10)-1)*4)*100} -> 0 | F14: 0.57424673 | G14: null hypothesis cannot be rejected | H14: {=INDIRECT("'C Impact of Technique'!M" & 3 + (ROW(A10)-1)*4)} -> 24.26946 | I14: {=INDIRECT("'C Impact of Technique'!M" & 4 + (ROW(A10)-1)*4)} -> 22.25922 | J14: {=INDIRECT("'C Impact of Technique'!Q" & 3 + (ROW(A10)-1)*4)*100} -> -8.2830026 | K14: 0.00012106938 | L14: medium | M14: T16 | N14: {=INDIRECT("'C Impact of Technique'!D" & 5 + (ROW(A10)-1)*4)} -> 1.047 | O14: {=INDIRECT("'C Impact of Technique'!D" & 6 + (ROW(A10)-1)*4)} -> 1.047 | P14: {=INDIRECT("'C Impact of Technique'!N" & 5 + (ROW(A10)-1)*4)*100} -> 0 | Q14: 0.71718881 | R14: null hypothesis cannot be rejected | S14: {=INDIRECT("'C Impact of Technique'!M" & 5 + (ROW(A10)-1)*4)} -> 23.5575 | T14: {=INDIRECT("'C Impact of Technique'!M" & 6 + (ROW(A10)-1)*4)} -> 21.87183 | U14: {=INDIRECT("'C Impact of Technique'!Q" & 5 + (ROW(A10)-1)*4)*100} -> -7.1555556 | V14: 5.1013909e-05 | W14: large | X14: =AVERAGE(J14,U14) -> -7.7192791
B15: T17 | C15: {=INDIRECT("'C Impact of Technique'!D" & 3 + (ROW(A11)-1)*4)} -> 1.047 | D15: {=INDIRECT("'C Impact of Technique'!D" & 4 + (ROW(A11)-1)*4)} -> 1.047 | E15: {=INDIRECT("'C Impact of Technique'!N" & 3 + (ROW(A11)-1)*4)*100} -> 0 | F15: 0.33285469 | G15: null hypothesis cannot be rejected | H15: {=INDIRECT("'C Impact of Technique'!M" & 3 + (ROW(A11)-1)*4)} -> 24.48933 | I15: {=INDIRECT("'C Impact of Technique'!M" & 4 + (ROW(A11)-1)*4)} -> 24.03912 | J15: {=INDIRECT("'C Impact of Technique'!Q" & 3 + (ROW(A11)-1)*4)*100} -> -1.8383925 | K15: 0.35163697 | L15: null hypothesis cannot be rejected | M15: T17 | N15: {=INDIRECT("'C Impact of Technique'!D" & 5 + (ROW(A11)-1)*4)} -> 1.047 | O15: {=INDIRECT("'C Impact of Technique'!D" & 6 + (ROW(A11)-1)*4)} -> 1.047 | P15: {=INDIRECT("'C Impact of Technique'!N" & 5 + (ROW(A11)-1)*4)*100} -> 0 | Q15: 0.84758748 | R15: null hypothesis cannot be rejected | S15: {=INDIRECT("'C Impact of Technique'!M" & 5 + (ROW(A11)-1)*4)} -> 23.88207 | T15: {=INDIRECT("'C Impact of Technique'!M" & 6 + (ROW(A11)-1)*4)} -> 23.71455 | U15: {=INDIRECT("'C Impact of Technique'!Q" & 5 + (ROW(A11)-1)*4)*100} -> -0.70144673 | V15: 0.58436242 | W15: null hypothesis cannot be rejected | X15: =AVERAGE(J15,U15) -> -1.2699196
B16: T19 | C16: {=INDIRECT("'C Impact of Technique'!D" & 3 + (ROW(A12)-1)*4)} -> 12.95 | D16: {=INDIRECT("'C Impact of Technique'!D" & 4 + (ROW(A12)-1)*4)} -> 12.733 | E16: {=INDIRECT("'C Impact of Technique'!N" & 3 + (ROW(A12)-1)*4)*100} -> -1.6756757 | F16: 0.16016394 | G16: null hypothesis cannot be rejected | H16: {=INDIRECT("'C Impact of Technique'!M" & 3 + (ROW(A12)-1)*4)} -> 661.6155 | I16: {=INDIRECT("'C Impact of Technique'!M" & 4 + (ROW(A12)-1)*4)} -> 681.97948 | J16: {=INDIRECT("'C Impact of Technique'!Q" & 3 + (ROW(A12)-1)*4)*100} -> 3.0779176 | K16: 2.7769586e-06 | L16: large | M16: T19 | N16: {=INDIRECT("'C Impact of Technique'!D" & 5 + (ROW(A12)-1)*4)} -> 1.57 | O16: {=INDIRECT("'C Impact of Technique'!D" & 6 + (ROW(A12)-1)*4)} -> 1.577 | P16: {=INDIRECT("'C Impact of Technique'!N" & 5 + (ROW(A12)-1)*4)*100} -> 0.44585987 | Q16: 2.8719491e-11 | R16: null hypothesis cannot be rejected | S16: {=INDIRECT("'C Impact of Technique'!M" & 5 + (ROW(A12)-1)*4)} -> 51.3076 | T16: {=INDIRECT("'C Impact of Technique'!M" & 6 + (ROW(A12)-1)*4)} -> 57.97052 | U16: {=INDIRECT("'C Impact of Technique'!Q" & 5 + (ROW(A12)-1)*4)*100} -> 12.986224 | V16: 3.8787145e-11 | W16: large | X16: =AVERAGE(J16,U16) -> 8.0320709
B17: T20 | C17: {=INDIRECT("'C Impact of Technique'!D" & 3 + (ROW(A13)-1)*4)} -> 8.901 | D17: {=INDIRECT("'C Impact of Technique'!D" & 4 + (ROW(A13)-1)*4)} -> 3.142 | E17: {=INDIRECT("'C Impact of Technique'!N" & 3 + (ROW(A13)-1)*4)*100} -> -64.700595 | F17: 2.8719491e-11 | G17: large | H17: {=INDIRECT("'C Impact of Technique'!M" & 3 + (ROW(A13)-1)*4)} -> 423.06453 | I17: {=INDIRECT("'C Impact of Technique'!M" & 4 + (ROW(A13)-1)*4)} -> 138.84498 | J17: {=INDIRECT("'C Impact of Technique'!Q" & 3 + (ROW(A13)-1)*4)*100} -> -67.181134 | K17: 2.8719491e-11 | L17: large | M17: T20 | N17: {=INDIRECT("'C Impact of Technique'!D" & 5 + (ROW(A13)-1)*4)} -> 1.1 | O17: {=INDIRECT("'C Impact of Technique'!D" & 6 + (ROW(A13)-1)*4)} -> 1.576 | P17: {=INDIRECT("'C Impact of Technique'!N" & 5 + (ROW(A13)-1)*4)*100} -> 43.272727 | Q17: 7.0436208e-10 | R17: large | S17: {=INDIRECT("'C Impact of Technique'!M" & 5 + (ROW(A13)-1)*4)} -> 29.491 | T17: {=INDIRECT("'C Impact of Technique'!M" & 6 + (ROW(A13)-1)*4)} -> 44.19104 | U17: {=INDIRECT("'C Impact of Technique'!Q" & 5 + (ROW(A13)-1)*4)*100} -> 49.845851 | V17: 8.1210731e-09 | W17: large | X17: =AVERAGE(J17,U17) -> -8.6676415
B18: T25 | C18: {=INDIRECT("'C Impact of Technique'!D" & 3 + (ROW(A14)-1)*4)} -> 18.85 | D18: {=INDIRECT("'C Impact of Technique'!D" & 4 + (ROW(A14)-1)*4)} -> 15.737 | E18: {=INDIRECT("'C Impact of Technique'!N" & 3 + (ROW(A14)-1)*4)*100} -> -16.514589 | F18: 2.8719491e-11 | G18: large | H18: {=INDIRECT("'C Impact of Technique'!M" & 3 + (ROW(A14)-1)*4)} -> 1018.0885 | I18: {=INDIRECT("'C Impact of Technique'!M" & 4 + (ROW(A14)-1)*4)} -> 837.05103 | J18: {=INDIRECT("'C Impact of Technique'!Q" & 3 + (ROW(A14)-1)*4)*100} -> -17.782096 | K18: 2.8719491e-11 | L18: large | M18: T25 | N18: {=INDIRECT("'C Impact of Technique'!D" & 5 + (ROW(A14)-1)*4)} -> 4.729 | O18: {=INDIRECT("'C Impact of Technique'!D" & 6 + (ROW(A14)-1)*4)} -> 3.682 | P18: {=INDIRECT("'C Impact of Technique'!N" & 5 + (ROW(A14)-1)*4)*100} -> -22.139987 | Q18: 2.8719491e-11 | R18: large | S18: {=INDIRECT("'C Impact of Technique'!M" & 5 + (ROW(A14)-1)*4)} -> 222.87777 | T18: {=INDIRECT("'C Impact of Technique'!M" & 6 + (ROW(A14)-1)*4)} -> 169.1879 | U18: {=INDIRECT("'C Impact of Technique'!Q" & 5 + (ROW(A14)-1)*4)*100} -> -24.089379 | V18: 2.8719491e-11 | W18: large | X18: =AVERAGE(J18,U18) -> -20.935737
B19: T26 | C19: {=INDIRECT("'C Impact of Technique'!D" & 3 + (ROW(A15)-1)*4)} -> 18.325 | D19: {=INDIRECT("'C Impact of Technique'!D" & 4 + (ROW(A15)-1)*4)} -> 18.927 | E19: {=INDIRECT("'C Impact of Technique'!N" & 3 + (ROW(A15)-1)*4)*100} -> 3.2851296 | F19: 2.8719491e-11 | G19: large | H19: {=INDIRECT("'C Impact of Technique'!M" & 3 + (ROW(A15)-1)*4)} -> 918.449 | I19: {=INDIRECT("'C Impact of Technique'!M" & 4 + (ROW(A15)-1)*4)} -> 907.73892 | J19: {=INDIRECT("'C Impact of Technique'!Q" & 3 + (ROW(A15)-1)*4)*100} -> -1.166105 | K19: 0.014119269 | L19: medium | M19: T26 | N19: {=INDIRECT("'C Impact of Technique'!D" & 5 + (ROW(A15)-1)*4)} -> 5.254 | O19: {=INDIRECT("'C Impact of Technique'!D" & 6 + (ROW(A15)-1)*4)} -> 1.087 | P19: {=INDIRECT("'C Impact of Technique'!N" & 5 + (ROW(A15)-1)*4)*100} -> -79.311001 | Q19: 2.8719491e-11 | R19: large | S19: {=INDIRECT("'C Impact of Technique'!M" & 5 + (ROW(A15)-1)*4)} -> 237.16556 | T19: {=INDIRECT("'C Impact of Technique'!M" & 6 + (ROW(A15)-1)*4)} -> 25.94669 | U19: {=INDIRECT("'C Impact of Technique'!Q" & 5 + (ROW(A15)-1)*4)*100} -> -89.059672 | V19: 2.8719491e-11 | W19: large | X19: =AVERAGE(J19,U19) -> -45.112889
B20: T28 | C20: {=INDIRECT("'C Impact of Technique'!D" & 3 + (ROW(A16)-1)*4)} -> 9.948 | D20: {=INDIRECT("'C Impact of Technique'!D" & 4 + (ROW(A16)-1)*4)} -> 13.655 | E20: {=INDIRECT("'C Impact of Technique'!N" & 3 + (ROW(A16)-1)*4)*100} -> 37.263772 | F20: 2.8719491e-11 | G20: large | H20: {=INDIRECT("'C Impact of Technique'!M" & 3 + (ROW(A16)-1)*4)} -> 531.42216 | I20: {=INDIRECT("'C Impact of Technique'!M" & 4 + (ROW(A16)-1)*4)} -> 747.06505 | J20: {=INDIRECT("'C Impact of Technique'!Q" & 3 + (ROW(A16)-1)*4)*100} -> 40.578453 | K20: 2.8719491e-11 | L20: large | M20: T28 | N20: {=INDIRECT("'C Impact of Technique'!D" & 5 + (ROW(A16)-1)*4)} -> 2.705 | O20: {=INDIRECT("'C Impact of Technique'!D" & 6 + (ROW(A16)-1)*4)} -> 3.153 | P20: {=INDIRECT("'C Impact of Technique'!N" & 5 + (ROW(A16)-1)*4)*100} -> 16.561922 | Q20: 2.8719491e-11 | R20: large | S20: {=INDIRECT("'C Impact of Technique'!M" & 5 + (ROW(A16)-1)*4)} -> 116.61255 | T20: {=INDIRECT("'C Impact of Technique'!M" & 6 + (ROW(A16)-1)*4)} -> 134.0025 | U20: {=INDIRECT("'C Impact of Technique'!Q" & 5 + (ROW(A16)-1)*4)*100} -> 14.912589 | V20: 2.8719491e-11 | W20: large | X20: =AVERAGE(J20,U20) -> 27.745521
B21: T29 | C21: {=INDIRECT("'C Impact of Technique'!D" & 3 + (ROW(A17)-1)*4)} -> 1.047 | D21: {=INDIRECT("'C Impact of Technique'!D" & 4 + (ROW(A17)-1)*4)} -> 1.047 | E21: {=INDIRECT("'C Impact of Technique'!N" & 3 + (ROW(A17)-1)*4)*100} -> 0 | F21: 0.95284243 | G21: null hypothesis cannot be rejected | H21: {=INDIRECT("'C Impact of Technique'!M" & 3 + (ROW(A17)-1)*4)} -> 20.89812 | I21: {=INDIRECT("'C Impact of Technique'!M" & 4 + (ROW(A17)-1)*4)} -> 21.15987 | J21: {=INDIRECT("'C Impact of Technique'!Q" & 3 + (ROW(A17)-1)*4)*100} -> 1.252505 | K21: 0.56421471 | L21: null hypothesis cannot be rejected | M21: T29 | N21: {=INDIRECT("'C Impact of Technique'!D" & 5 + (ROW(A17)-1)*4)} -> 0.524 | O21: {=INDIRECT("'C Impact of Technique'!D" & 6 + (ROW(A17)-1)*4)} -> 0.523 | P21: {=INDIRECT("'C Impact of Technique'!N" & 5 + (ROW(A17)-1)*4)*100} -> -0.19083969 | Q21: 0.16016394 | R21: null hypothesis cannot be rejected | S21: {=INDIRECT("'C Impact of Technique'!M" & 5 + (ROW(A17)-1)*4)} -> 10.19704 | T21: {=INDIRECT("'C Impact of Technique'!M" & 6 + (ROW(A17)-1)*4)} -> 10.26126 | U21: {=INDIRECT("'C Impact of Technique'!Q" & 5 + (ROW(A17)-1)*4)*100} -> 0.62979061 | V21: 0.64672458 | W21: null hypothesis cannot be rejected | X21: =AVERAGE(J21,U21) -> 0.94114781
B22: T31 | C22: {=INDIRECT("'C Impact of Technique'!D" & 3 + (ROW(A18)-1)*4)} -> 16.18 | D22: {=INDIRECT("'C Impact of Technique'!D" & 4 + (ROW(A18)-1)*4)} -> 23.395 | E22: {=INDIRECT("'C Impact of Technique'!N" & 3 + (ROW(A18)-1)*4)*100} -> 44.592089 | F22: 2.8719491e-11 | G22: large | H22: {=INDIRECT("'C Impact of Technique'!M" & 3 + (ROW(A18)-1)*4)} -> 1067.2328 | I22: {=INDIRECT("'C Impact of Technique'!M" & 4 + (ROW(A18)-1)*4)} -> 1591.7958 | J22: {=INDIRECT("'C Impact of Technique'!Q" & 3 + (ROW(A18)-1)*4)*100} -> 49.151694 | K22: 2.8719491e-11 | L22: large | M22: T31 | N22: {=INDIRECT("'C Impact of Technique'!D" & 5 + (ROW(A18)-1)*4)} -> 12.467 | O22: {=INDIRECT("'C Impact of Technique'!D" & 6 + (ROW(A18)-1)*4)} -> 17.895 | P22: {=INDIRECT("'C Impact of Technique'!N" & 5 + (ROW(A18)-1)*4)*100} -> 43.538943 | Q22: 2.8719491e-11 | R22: large | S22: {=INDIRECT("'C Impact of Technique'!M" & 5 + (ROW(A18)-1)*4)} -> 850.62341 | T22: {=INDIRECT("'C Impact of Technique'!M" & 6 + (ROW(A18)-1)*4)} -> 1205.2282 | U22: {=INDIRECT("'C Impact of Technique'!Q" & 5 + (ROW(A18)-1)*4)*100} -> 41.687642 | V22: 2.8719491e-11 | W22: large | X22: =AVERAGE(J22,U22) -> 45.419668
B23: T32 | C23: {=INDIRECT("'C Impact of Technique'!D" & 3 + (ROW(A19)-1)*4)} -> 1.047 | D23: {=INDIRECT("'C Impact of Technique'!D" & 4 + (ROW(A19)-1)*4)} -> 1.048 | E23: {=INDIRECT("'C Impact of Technique'!N" & 3 + (ROW(A19)-1)*4)*100} -> 0.095510984 | F23: 0.64672458 | G23: null hypothesis cannot be rejected | H23: {=INDIRECT("'C Impact of Technique'!M" & 3 + (ROW(A19)-1)*4)} -> 32.22666 | I23: {=INDIRECT("'C Impact of Technique'!M" & 4 + (ROW(A19)-1)*4)} -> 31.74392 | J23: {=INDIRECT("'C Impact of Technique'!Q" & 3 + (ROW(A19)-1)*4)*100} -> -1.4979523 | K23: 0.23690664 | L23: null hypothesis cannot be rejected | M23: T32 | N23: {=INDIRECT("'C Impact of Technique'!D" & 5 + (ROW(A19)-1)*4)} -> 1.047 | O23: {=INDIRECT("'C Impact of Technique'!D" & 6 + (ROW(A19)-1)*4)} -> 1.047 | P23: {=INDIRECT("'C Impact of Technique'!N" & 5 + (ROW(A19)-1)*4)*100} -> 0 | Q23: 0.63614069 | R23: null hypothesis cannot be rejected | S23: {=INDIRECT("'C Impact of Technique'!M" & 5 + (ROW(A19)-1)*4)} -> 25.24317 | T23: {=INDIRECT("'C Impact of Technique'!M" & 6 + (ROW(A19)-1)*4)} -> 24.63591 | U23: {=INDIRECT("'C Impact of Technique'!Q" & 5 + (ROW(A19)-1)*4)*100} -> -2.4056408 | V23: 0.12967022 | W23: null hypothesis cannot be rejected | X23: =AVERAGE(J23,U23) -> -1.9517966
B24: T33 | C24: {=INDIRECT("'C Impact of Technique'!D" & 3 + (ROW(A20)-1)*4)} -> 1.047 | D24: {=INDIRECT("'C Impact of Technique'!D" & 4 + (ROW(A20)-1)*4)} -> 1.047 | E24: {=INDIRECT("'C Impact of Technique'!N" & 3 + (ROW(A20)-1)*4)*100} -> 0 | F24: 0.34782778 | G24: null hypothesis cannot be rejected | H24: {=INDIRECT("'C Impact of Technique'!M" & 3 + (ROW(A20)-1)*4)} -> 27.39999 | I24: {=INDIRECT("'C Impact of Technique'!M" & 4 + (ROW(A20)-1)*4)} -> 27.00213 | J24: {=INDIRECT("'C Impact of Technique'!Q" & 3 + (ROW(A20)-1)*4)*100} -> -1.4520443 | K24: 0.57424673 | L24: null hypothesis cannot be rejected | M24: T33 | N24: {=INDIRECT("'C Impact of Technique'!D" & 5 + (ROW(A20)-1)*4)} -> 1.047 | O24: {=INDIRECT("'C Impact of Technique'!D" & 6 + (ROW(A20)-1)*4)} -> 1.047 | P24: {=INDIRECT("'C Impact of Technique'!N" & 5 + (ROW(A20)-1)*4)*100} -> 0 | Q24: 0.71167263 | R24: null hypothesis cannot be rejected | S24: {=INDIRECT("'C Impact of Technique'!M" & 5 + (ROW(A20)-1)*4)} -> 22.24875 | T24: {=INDIRECT("'C Impact of Technique'!M" & 6 + (ROW(A20)-1)*4)} -> 23.7669 | U24: {=INDIRECT("'C Impact of Technique'!Q" & 5 + (ROW(A20)-1)*4)*100} -> 6.8235294 | V24: 0.00232223 | W24: null hypothesis cannot be rejected | X24: =AVERAGE(J24,U24) -> 2.6857425
... B30: T51 | C30: {=INDIRECT("'C Impact of Technique'!D" & 3 + (ROW(A26)-1)*4)} -> 90.43 | D30: {=INDIRECT("'C Impact of Technique'!D" & 4 + (ROW(A26)-1)*4)} -> 66.108 | E30: {=INDIRECT("'C Impact of Technique'!N" & 3 + (ROW(A26)-1)*4)*100} -> -26.895942 | F30: 2.8719491e-11 | G30: large | H30: {=INDIRECT("'C Impact of Technique'!M" & 3 + (ROW(A26)-1)*4)} -> 5767.6254 | I30: {=INDIRECT("'C Impact of Technique'!M" & 4 + (ROW(A26)-1)*4)} -> 4180.6699 | J30: {=INDIRECT("'C Impact of Technique'!Q" & 3 + (ROW(A26)-1)*4)*100} -> -27.514885 | K30: 2.8719491e-11 | L30: large | M30: T51 | N30: {=INDIRECT("'C Impact of Technique'!D" & 5 + (ROW(A26)-1)*4)} -> 33.163 | O30: {=INDIRECT("'C Impact of Technique'!D" & 6 + (ROW(A26)-1)*4)} -> 24.194 | P30: {=INDIRECT("'C Impact of Technique'!N" & 5 + (ROW(A26)-1)*4)*100} -> -27.045201 | Q30: 2.8719491e-11 | R30: large | S30: {=INDIRECT("'C Impact of Technique'!M" & 5 + (ROW(A26)-1)*4)} -> 2127.7381 | T30: {=INDIRECT("'C Impact of Technique'!M" & 6 + (ROW(A26)-1)*4)} -> 1511.1572 | U30: {=INDIRECT("'C Impact of Technique'!Q" & 5 + (ROW(A26)-1)*4)*100} -> -28.97823 | V30: 2.8719491e-11 | W30: large | X30: =AVERAGE(J30,U30) -> -28.246557
B32: Impact
B33: Energy consumption (J) | G33: Energy consumption (J) | L33: Energy consumption (J)
B34: Optimization level O0 | G34: Optimization level O3 | L34: Optimization level O0 + Optimization level O3
B35: Impact | C35: Average | D35: Min | E35: Max | G35: Impact | H35: Average | I35: Min | J35: Max | L35: Impact | M35: Average | N35: Min | O35: Max
B36: Reduction | C36: {=AVERAGE(_xlfn._xlws.FILTER($J$5:$J$30, ISNUMBER(MATCH($B$5:$B$30, _xlfn.TEXTSPLIT(_xlfn.TEXTJOIN(", ", TRUE, AA6:AA8), ", "), 0))))} -> -35.280108 | D36: {=MIN(_xlfn._xlws.FILTER($J$5:$J$30, ISNUMBER(MATCH($B$5:$B$30, _xlfn.TEXTSPLIT(_xlfn.TEXTJOIN(", ", TRUE, AA6:AA8), ", "), 0))))} -> -99.557975 | E36: {=MAX(_xlfn._xlws.FILTER($J$5:$J$30, ISNUMBER(MATCH($B$5:$B$30, _xlfn.TEXTSPLIT(_xlfn.TEXTJOIN(", ", TRUE, AA6:AA8), ", "), 0))))} -> -8.2830026 | G36: Reduction | H36: {=AVERAGE(_xlfn._xlws.FILTER($U$5:$U$30, ISNUMBER(MATCH($M$5:$M$30, _xlfn.TEXTSPLIT(_xlfn.TEXTJOIN(", ", TRUE, AD6:AD8), ", "), 0))))} -> -45.331696 | I36: {=MIN(_xlfn._xlws.FILTER($U$5:$U$30, ISNUMBER(MATCH($M$5:$M$30, _xlfn.TEXTSPLIT(_xlfn.TEXTJOIN(", ", TRUE, AD6:AD8), ", "), 0))))} -> -99.810559 | J36: {=MAX(_xlfn._xlws.FILTER($U$5:$U$30, ISNUMBER(MATCH($M$5:$M$30, _xlfn.TEXTSPLIT(_xlfn.TEXTJOIN(", ", TRUE, AD6:AD8), ", "), 0))))} -> -4.8045026 | L36: Reduction | M36: =AVERAGE(C36,H36) -> -40.305902 | N36: =MIN(D36,I36) -> -99.810559 | O36: =MAX(E36,J36) -> -4.8045026
B37: No impact | C37: {=AVERAGE(_xlfn._xlws.FILTER($J$5:$J$30, ISNUMBER(MATCH($B$5:$B$30, _xlfn.TEXTSPLIT(_xlfn.TEXTJOIN(", ", TRUE, AA9), ", "), 0))))} -> -1.1081087 | D37: {=MIN(_xlfn._xlws.FILTER($J$5:$J$30, ISNUMBER(MATCH($B$5:$B$30, _xlfn.TEXTSPLIT(_xlfn.TEXTJOIN(", ", TRUE, AA9), ", "), 0))))} -> -2.2887324 | E37: {=MAX(_xlfn._xlws.FILTER($J$5:$J$30, ISNUMBER(MATCH($B$5:$B$30, _xlfn.TEXTSPLIT(_xlfn.TEXTJOIN(", ", TRUE, AA9), ", "), 0))))} -> 1.252505 | G37: No impact | H37: {=AVERAGE(_xlfn._xlws.FILTER($U$5:$U$30, ISNUMBER(MATCH($M$5:$M$30, _xlfn.TEXTSPLIT(_xlfn.TEXTJOIN(", ", TRUE, AD9), ", "), 0))))} -> 0.16948658 | I37: {=MIN(_xlfn._xlws.FILTER($U$5:$U$30, ISNUMBER(MATCH($M$5:$M$30, _xlfn.TEXTSPLIT(_xlfn.TEXTJOIN(", ", TRUE, AD9), ", "), 0))))} -> -2.4056408 | J37: {=MAX(_xlfn._xlws.FILTER($U$5:$U$30, ISNUMBER(MATCH($M$5:$M$30, _xlfn.TEXTSPLIT(_xlfn.TEXTJOIN(", ", TRUE, AD9), ", "), 0))))} -> 2.4753748 | L37: No impact | M37: =AVERAGE(C37,H37) -> -0.46931105 | N37: =MIN(D37,I37) -> -2.4056408 | O37: =MAX(E37,J37) -> 2.4753748
B38: Increase | C38: {=AVERAGE(_xlfn._xlws.FILTER($J$5:$J$30, ISNUMBER(MATCH($B$5:$B$30, _xlfn.TEXTSPLIT(_xlfn.TEXTJOIN(", ", TRUE, AA10:AA12), ", "), 0))))} -> 30.082509 | D38: {=MIN(_xlfn._xlws.FILTER($J$5:$J$30, ISNUMBER(MATCH($B$5:$B$30, _xlfn.TEXTSPLIT(_xlfn.TEXTJOIN(", ", TRUE, AA10:AA12), ", "), 0))))} -> 3.0779176 | E38: {=MAX(_xlfn._xlws.FILTER($J$5:$J$30, ISNUMBER(MATCH($B$5:$B$30, _xlfn.TEXTSPLIT(_xlfn.TEXTJOIN(", ", TRUE, AA10:AA12), ", "), 0))))} -> 53.467905 | G38: Increase | H38: {=AVERAGE(_xlfn._xlws.FILTER($U$5:$U$30, ISNUMBER(MATCH($M$5:$M$30, _xlfn.TEXTSPLIT(_xlfn.TEXTJOIN(", ", TRUE, AD10:AD12), ", "), 0))))} -> 70.079325 | I38: {=MIN(_xlfn._xlws.FILTER($U$5:$U$30, ISNUMBER(MATCH($M$5:$M$30, _xlfn.TEXTSPLIT(_xlfn.TEXTJOIN(", ", TRUE, AD10:AD12), ", "), 0))))} -> 6.5358212 | J38: {=MAX(_xlfn._xlws.FILTER($U$5:$U$30, ISNUMBER(MATCH($M$5:$M$30, _xlfn.TEXTSPLIT(_xlfn.TEXTJOIN(", ", TRUE, AD10:AD12), ", "), 0))))} -> 357.76362 | L38: Increase | M38: =AVERAGE(C38,H38) -> 50.080917 | N38: =MIN(D38,I38) -> 3.0779176 | O38: =MAX(E38,J38) -> 357.76362
B39: Total | C39: {=AVERAGE(_xlfn._xlws.FILTER($J$5:$J$30, ISNUMBER(MATCH($B$5:$B$30, _xlfn.TEXTSPLIT(_xlfn.TEXTJOIN(", ", TRUE, AA6:AA12), ", "), 0))))} -> -10.881605 | D39: {=MIN(_xlfn._xlws.FILTER($J$5:$J$30, ISNUMBER(MATCH($B$5:$B$30, _xlfn.TEXTSPLIT(_xlfn.TEXTJOIN(", ", TRUE, AA6:AA12), ", "), 0))))} -> -99.557975 | E39: {=MAX(_xlfn._xlws.FILTER($J$5:$J$30, ISNUMBER(MATCH($B$5:$B$30, _xlfn.TEXTSPLIT(_xlfn.TEXTJOIN(", ", TRUE, AA6:AA12), ", "), 0))))} -> 53.467905 | G39: Total | H39: {=AVERAGE(_xlfn._xlws.FILTER($U$5:$U$30, ISNUMBER(MATCH($M$5:$M$30, _xlfn.TEXTSPLIT(_xlfn.TEXTJOIN(", ", TRUE, AD6:AD12), ", "), 0))))} -> -5.5092705 | I39: {=MIN(_xlfn._xlws.FILTER($U$5:$U$30, ISNUMBER(MATCH($M$5:$M$30, _xlfn.TEXTSPLIT(_xlfn.TEXTJOIN(", ", TRUE, AD6:AD12), ", "), 0))))} -> -99.810559 | J39: {=MAX(_xlfn._xlws.FILTER($U$5:$U$30, ISNUMBER(MATCH($M$5:$M$30, _xlfn.TEXTSPLIT(_xlfn.TEXTJOIN(", ", TRUE, AD6:AD12), ", "), 0))))} -> 357.76362 | L39: Total | M39: =AVERAGE(C39,H39) -> -8.1954376 | N39: =MIN(D39,I39) -> -99.810559 | O39: =MAX(E39,J39) -> 357.76362
B41: Techniques
B42: Energy consumption (J) | G42: Energy consumption (J) | L42: Energy consumption (J)
B43: Optimization level O0 | G43: Optimization level O3 | L43: Optimization level O0 + Optimization level O3
B44: Impact | C44: Nº | E44: % | G44: Impact | H44: Nº | J44: % | L44: Impact | M44: Nº | O44: %
B45: Reduction | C45: {=COUNT(_xlfn._xlws.FILTER($J$5:$J$30, ISNUMBER(MATCH($B$5:$B$30, _xlfn.TEXTSPLIT(_xlfn.TEXTJOIN(", ", TRUE, AA6:AA8), ", "), 0))))} -> 12 | E45: =C45/C$48 -> 0.46153846 | G45: Reduction | H45: {=COUNT(_xlfn._xlws.FILTER($U$5:$U$30, ISNUMBER(MATCH($M$5:$M$30, _xlfn.TEXTSPLIT(_xlfn.TEXTJOIN(", ", TRUE, AD6:AD8), ", "), 0))))} -> 14 | J45: =H45/H$48 -> 0.53846154 | L45: Reduction | M45: =SUM(C45,H45) -> 26 | O45: =M45/M$48 -> 0.5
B46: No impact | C46: {=COUNT(_xlfn._xlws.FILTER($J$5:$J$30, ISNUMBER(MATCH($B$5:$B$30, _xlfn.TEXTSPLIT(_xlfn.TEXTJOIN(", ", TRUE, AA9), ", "), 0))))} -> 9 | E46: =C46/C$48 -> 0.34615385 | G46: No impact | H46: {=COUNT(_xlfn._xlws.FILTER($U$5:$U$30, ISNUMBER(MATCH($M$5:$M$30, _xlfn.TEXTSPLIT(_xlfn.TEXTJOIN(", ", TRUE, AD9), ", "), 0))))} -> 5 | J46: =H46/H$48 -> 0.19230769 | L46: No impact | M46: =SUM(C46,H46) -> 14 | O46: =M46/M$48 -> 0.26923077
B47: Increase | C47: {=COUNT(_xlfn._xlws.FILTER($J$5:$J$30, ISNUMBER(MATCH($B$5:$B$30, _xlfn.TEXTSPLIT(_xlfn.TEXTJOIN(", ", TRUE, AA10:AA12), ", "), 0))))} -> 5 | E47: =C47/C$48 -> 0.19230769 | G47: Increase | H47: {=COUNT(_xlfn._xlws.FILTER($U$5:$U$30, ISNUMBER(MATCH($M$5:$M$30, _xlfn.TEXTSPLIT(_xlfn.TEXTJOIN(", ", TRUE, AD10:AD12), ", "), 0))))} -> 7 | J47: =H47/H$48 -> 0.26923077 | L47: Increase | M47: =SUM(C47,H47) -> 12 | O47: =M47/M$48 -> 0.23076923
B48: Total | C48: =SUM(C45:D47) -> 26 | E48: =C48/C$48 -> 1 | G48: Total | H48: =SUM(H45:I47) -> 26 | J48: =H48/H$48 -> 1 | L48: Total | M48: =SUM(M45:N47) -> 52 | O48: =M48/M$48 -> 1

Sheet C Optimization results
C2: Test1 | N2: Test2
C3: Time (s) | H3: Energy consumption (J) | N3: Time (s) | S3: Energy consumption (J) | Z3: Energy consumption (J) | AC3: Energy consumption (J)
B4: Technique | C4: Optimization level O0 | D4: Optimization level O3 | E4: Impact (%) | F4: p-value | G4: Effect size | H4: Optimization level O0 | I4: Optimization level O3 | J4: Impact (%) | K4: p-value | L4: Effect size | M4: Technique | N4: Optimization level O0 | O4: Optimization level O3 | P4: Impact (%) | Q4: p-value | R4: Effect size | S4: Optimization level O0 | T4: Optimization level O3 | U4: Impact (%) | V4: p-value | W4: Effect size | X4: Average impact (%) | Z4: Test1 | AC4: Test2
B5: T4 | C5: {=INDIRECT("'C Impact of Optimization'!D" & 3 + (ROW(A1)-1)*4)} -> 4.713 | D5: {=INDIRECT("'C Impact of Optimization'!D" & 4 + (ROW(A1)-1)*4)} -> 3.071 | E5: {=INDIRECT("'C Impact of Optimization'!N" & 3 + (ROW(A1)-1)*4)*100} -> -34.839805 | F5: 2.8719491e-11 | G5: large | H5: {=INDIRECT("'C Impact of Optimization'!M" & 3 + (ROW(A1)-1)*4)} -> 242.2482 | I5: {=INDIRECT("'C Impact of Optimization'!M" & 4 + (ROW(A1)-1)*4)} -> 138.5021 | J5: {=INDIRECT("'C Impact of Optimization'!Q" & 3 + (ROW(A1)-1)*4)*100} -> -42.826366 | K5: 2.8719491e-11 | L5: large | M5: T4 | N5: {=INDIRECT("'C Impact of Optimization'!D" & 5 + (ROW(A1)-1)*4)} -> 3.665 | O5: {=INDIRECT("'C Impact of Optimization'!D" & 6 + (ROW(A1)-1)*4)} -> 1.048 | P5: {=INDIRECT("'C Impact of Optimization'!N" & 5 + (ROW(A1)-1)*4)*100} -> -71.405184 | Q5: 2.8719491e-11 | R5: large | S5: {=INDIRECT("'C Impact of Optimization'!M" & 5 + (ROW(A1)-1)*4)} -> 164.66845 | T5: {=INDIRECT("'C Impact of Optimization'!M" & 6 + (ROW(A1)-1)*4)} -> 31.77536 | U5: {=INDIRECT("'C Impact of Optimization'!Q" & 5 + (ROW(A1)-1)*4)*100} -> -80.703432 | V5: 2.8719491e-11 | W5: large | X5: =AVERAGE(J5,U5) -> -61.764899 | Z5: Impact | AA5: Techniques | AC5: Impact | AD5: Techniques
B6: T5 | C6: {=INDIRECT("'C Impact of Optimization'!D" & 3 + (ROW(A2)-1)*4)} -> 409.731 | D6: {=INDIRECT("'C Impact of Optimization'!D" & 4 + (ROW(A2)-1)*4)} -> 21.569 | E6: {=INDIRECT("'C Impact of Optimization'!N" & 3 + (ROW(A2)-1)*4)*100} -> -94.735814 | F6: 2.8719491e-11 | G6: large | H6: {=INDIRECT("'C Impact of Optimization'!M" & 3 + (ROW(A2)-1)*4)} -> 24903.45 | I6: {=INDIRECT("'C Impact of Optimization'!M" & 4 + (ROW(A2)-1)*4)} -> 1134.7451 | J6: {=INDIRECT("'C Impact of Optimization'!Q" & 3 + (ROW(A2)-1)*4)*100} -> -95.443422 | K6: 2.8719491e-11 | L6: large | M6: T5 | N6: {=INDIRECT("'C Impact of Optimization'!D" & 5 + (ROW(A2)-1)*4)} -> 400.362 | O6: {=INDIRECT("'C Impact of Optimization'!D" & 6 + (ROW(A2)-1)*4)} -> 20.49 | P6: {=INDIRECT("'C Impact of Optimization'!N" & 5 + (ROW(A2)-1)*4)*100} -> -94.882132 | Q6: 2.8719491e-11 | R6: large | S6: {=INDIRECT("'C Impact of Optimization'!M" & 5 + (ROW(A2)-1)*4)} -> 24354.02 | T6: {=INDIRECT("'C Impact of Optimization'!M" & 6 + (ROW(A2)-1)*4)} -> 1208.91 | U6: {=INDIRECT("'C Impact of Optimization'!Q" & 5 + (ROW(A2)-1)*4)*100} -> -95.036097 | V6: 2.8719491e-11 | W6: large | X6: =AVERAGE(J6,U6) -> -95.239759 | Z6: <= -75 | AA6: {=_xlfn.TEXTJOIN(", ", TRUE, IF(J5:J30 <= -75, B5:B30, ""))} -> T5, T19, T20, T25, T28, T36, T49, T50 | AC6: <= -75 | AD6: {=_xlfn.TEXTJOIN(", ", TRUE, IF(U5:U30 <= -75, M5:M30, ""))} -> T4, T5, T19, T25, T26, T28, T36, T40, T50
B7: T7 | C7: {=INDIRECT("'C Impact of Optimization'!D" & 3 + (ROW(A3)-1)*4)} -> 2.094 | D7: {=INDIRECT("'C Impact of Optimization'!D" & 4 + (ROW(A3)-1)*4)} -> 2.094 | E7: {=INDIRECT("'C Impact of Optimization'!N" & 3 + (ROW(A3)-1)*4)*100} -> 0 | F7: 0.21701682 | G7: null hypothesis cannot be rejected | H7: {=INDIRECT("'C Impact of Optimization'!M" & 3 + (ROW(A3)-1)*4)} -> 71.7195 | I7: {=INDIRECT("'C Impact of Optimization'!M" & 4 + (ROW(A3)-1)*4)} -> 68.4738 | J7: {=INDIRECT("'C Impact of Optimization'!Q" & 3 + (ROW(A3)-1)*4)*100} -> -4.5255474 | K7: 0.014710444 | L7: medium | M7: T7 | N7: {=INDIRECT("'C Impact of Optimization'!D" & 5 + (ROW(A3)-1)*4)} -> 1.047 | O7: {=INDIRECT("'C Impact of Optimization'!D" & 6 + (ROW(A3)-1)*4)} -> 1.047 | P7: {=INDIRECT("'C Impact of Optimization'!N" & 5 + (ROW(A3)-1)*4)*100} -> 0 | Q7: 0.55426784 | R7: null hypothesis cannot be rejected | S7: {=INDIRECT("'C Impact of Optimization'!M" & 5 + (ROW(A3)-1)*4)} -> 31.43094 | T7: {=INDIRECT("'C Impact of Optimization'!M" & 6 + (ROW(A3)-1)*4)} -> 30.28971 | U7: {=INDIRECT("'C Impact of Optimization'!Q" & 5 + (ROW(A3)-1)*4)*100} -> -3.6309127 | V7: 0.44201791 | W7: small | X7: =AVERAGE(J7,U7) -> -4.0782301 | Z7: > -75 & <= -25 | AA7: {=_xlfn.TEXTJOIN(", ", TRUE, IF((J5:J30 > -75) * (J5:J30 <= -25), B5:B30, ""))} -> T4, T11, T13, T26, T29, T40, T44, T51 | AC7: > -75 & <= -25 | AD7: {=_xlfn.TEXTJOIN(", ", TRUE, IF((U5:U30 > -75) * (U5:U30 <= -25), M5:M30, ""))} -> T10, T11, T12, T13, T20, T29, T44, T49, T51
